0,NameError,name 'math' is not defined,0,,2023-05-08 15:05:36.667052,"[('weird_numbers = make_array(-2, math.floor(12.6), 3, math.pow(5, math.ceil(5.3)))', 4)]","['Traceback (most recent call last):', '  File ""/opt/conda/lib/python3.10/site-packages/IPython/core/interactiveshell.py"", line 3508, in run_code', '    exec(code_obj, self.user_global_ns, self.user_ns)', '  File ""/tmp/ipykernel_4323/1353906065.py"", line 4, in <module>', '    weird_numbers = make_array(-2, math.floor(12.6), 3, math.pow(5, math.ceil(5.3)))', ""NameError: name 'math' is not defined""]"
1,AttributeError,module 'numpy' has no attribute 'make_array',0,,2023-05-08 15:05:58.014749,"[('weird_numbers = np.make_array(-2, math.floor(12.6), 3, math.pow(5, math.ceil(5.3)))', 4), ('raise AttributeError(""module {!r} has no attribute ""', 311)]","['Traceback (most recent call last):', '  File ""/opt/conda/lib/python3.10/site-packages/IPython/core/interactiveshell.py"", line 3508, in run_code', '    exec(code_obj, self.user_global_ns, self.user_ns)', '  File ""/tmp/ipykernel_4323/3840564184.py"", line 4, in <module>', '    weird_numbers = np.make_array(-2, math.floor(12.6), 3, math.pow(5, math.ceil(5.3)))', '  File ""/opt/conda/lib/python3.10/site-packages/numpy/__init__.py"", line 311, in __getattr__', '    raise AttributeError(""module {!r} has no attribute ""', ""AttributeError: module 'numpy' has no attribute 'make_array'""]"
2,NameError,name 'array' is not defined,0,,2023-05-08 15:06:52.726636,"[('weird_numbers = array(-2, math.floor(12.6), 3, math.pow(5, math.ceil(5.3)))', 4)]","['Traceback (most recent call last):', '  File ""/opt/conda/lib/python3.10/site-packages/IPython/core/interactiveshell.py"", line 3508, in run_code', '    exec(code_obj, self.user_global_ns, self.user_ns)', '  File ""/tmp/ipykernel_4323/2150816414.py"", line 4, in <module>', '    weird_numbers = array(-2, math.floor(12.6), 3, math.pow(5, math.ceil(5.3)))', ""NameError: name 'array' is not defined""]"
3,NameError,name 'math' is not defined,0,,2023-05-08 15:07:06.688755,"[('weird_numbers = np.array(-2, math.floor(12.6), 3, math.pow(5, math.ceil(5.3)))', 4)]","['Traceback (most recent call last):', '  File ""/opt/conda/lib/python3.10/site-packages/IPython/core/interactiveshell.py"", line 3508, in run_code', '    exec(code_obj, self.user_global_ns, self.user_ns)', '  File ""/tmp/ipykernel_4323/550805355.py"", line 4, in <module>', '    weird_numbers = np.array(-2, math.floor(12.6), 3, math.pow(5, math.ceil(5.3)))', ""NameError: name 'math' is not defined""]"
4,AttributeError,module 'numpy' has no attribute 'make_array',0,,2023-05-10 18:36:12.399892,"[('weird_numbers = np.make_array(-2, math.floor(12.6), 3, math.pow(5, math.ceil(5.3)))', 4), ('raise AttributeError(""module {!r} has no attribute ""', 311)]","['Traceback (most recent call last):', '  File ""/opt/conda/lib/python3.10/site-packages/IPython/core/interactiveshell.py"", line 3508, in run_code', '    exec(code_obj, self.user_global_ns, self.user_ns)', '  File ""/tmp/ipykernel_129/3840564184.py"", line 4, in <module>', '    weird_numbers = np.make_array(-2, math.floor(12.6), 3, math.pow(5, math.ceil(5.3)))', '  File ""/opt/conda/lib/python3.10/site-packages/numpy/__init__.py"", line 311, in __getattr__', '    raise AttributeError(""module {!r} has no attribute ""', ""AttributeError: module 'numpy' has no attribute 'make_array'""]"
5,NameError,name 'math' is not defined,0,,2023-05-10 18:36:43.738263,"[('weird_numbers = make_array(-2, math.floor(12.6), 3, math.pow(5, math.ceil(5.3)))', 4)]","['Traceback (most recent call last):', '  File ""/opt/conda/lib/python3.10/site-packages/IPython/core/interactiveshell.py"", line 3508, in run_code', '    exec(code_obj, self.user_global_ns, self.user_ns)', '  File ""/tmp/ipykernel_129/1353906065.py"", line 4, in <module>', '    weird_numbers = make_array(-2, math.floor(12.6), 3, math.pow(5, math.ceil(5.3)))', ""NameError: name 'math' is not defined""]"
6,NameError,name 'failthful_with_eruption_nums' is not defined,0,,2023-05-10 19:15:18.114861,"[('first_nine_waiting_times = failthful_with_eruption_nums.where(""eruption number"", are.between_or_equal_to(1, 9)).select(""waiting"")', 5)]","['Traceback (most recent call last):', '  File ""/opt/conda/lib/python3.10/site-packages/IPython/core/interactiveshell.py"", line 3508, in run_code', '    exec(code_obj, self.user_global_ns, self.user_ns)', '  File ""/tmp/ipykernel_129/4120427273.py"", line 5, in <module>', '    first_nine_waiting_times = failthful_with_eruption_nums.where(""eruption number"", are.between_or_equal_to(1, 9)).select(""waiting"")', ""NameError: name 'failthful_with_eruption_nums' is not defined""]"
7,TypeError,unsupported operand type(s) for +: 'int' and 'str',0,,2023-05-10 19:15:34.317878,"[('total_waiting_time_until_tenth = sum(first_nine_waiting_times)', 6)]","['Traceback (most recent call last):', '  File ""/opt/conda/lib/python3.10/site-packages/IPython/core/interactiveshell.py"", line 3508, in run_code', '    exec(code_obj, self.user_global_ns, self.user_ns)', '  File ""/tmp/ipykernel_129/3095374111.py"", line 6, in <module>', '    total_waiting_time_until_tenth = sum(first_nine_waiting_times)', ""TypeError: unsupported operand type(s) for +: 'int' and 'str'""]"
8,TypeError,"int() argument must be a string, a bytes-like object or a real number, not 'Table'",0,,2023-05-10 19:16:16.185609,"[('total_waiting_time_until_tenth = sum(int(first_nine_waiting_times))', 6)]","['Traceback (most recent call last):', '  File ""/opt/conda/lib/python3.10/site-packages/IPython/core/interactiveshell.py"", line 3508, in run_code', '    exec(code_obj, self.user_global_ns, self.user_ns)', '  File ""/tmp/ipykernel_129/1333727534.py"", line 6, in <module>', '    total_waiting_time_until_tenth = sum(int(first_nine_waiting_times))', ""TypeError: int() argument must be a string, a bytes-like object or a real number, not 'Table'""]"
9,IndexError,index 9 is out of bounds for axis 0 with size 9,0,,2023-05-10 19:29:34.098716,"[('first_nine_waiting_times = faithful_with_eruption_nums.where(""eruption number"", are.between_or_equal_to(1, 9)).select(""waiting"").take(1, 2, 3, 4, 5, 6, 7, 8, 9)', 6), ('return self.__getitem__(all_args)', 5949)]","['Traceback (most recent call last):', '  File ""/opt/conda/lib/python3.10/site-packages/IPython/core/interactiveshell.py"", line 3508, in run_code', '    exec(code_obj, self.user_global_ns, self.user_ns)', '  File ""/tmp/ipykernel_129/2550875282.py"", line 6, in <module>', '    first_nine_waiting_times = faithful_with_eruption_nums.where(""eruption number"", are.between_or_equal_to(1, 9)).select(""waiting"").take(1, 2, 3, 4, 5, 6, 7, 8, 9)', '  File ""/opt/conda/lib/python3.10/site-packages/datascience/tables.py"", line 5949, in __call__', '    return self.__getitem__(all_args)', '  File ""/opt/conda/lib/python3.10/site-packages/datascience/tables.py"", line 6015, in __getitem__', '    columns = [np.take(column, row_indices_or_slice, axis=0)', '  File ""/opt/conda/lib/python3.10/site-packages/datascience/tables.py"", line 6015, in <listcomp>', '    columns = [np.take(column, row_indices_or_slice, axis=0)', '  File ""<__array_function__ internals>"", line 180, in take', '  File ""/opt/conda/lib/python3.10/site-packages/numpy/core/fromnumeric.py"", line 190, in take', ""    return _wrapfunc(a, 'take', indices, axis=axis, out=out, mode=mode)"", '  File ""/opt/conda/lib/python3.10/site-packages/numpy/core/fromnumeric.py"", line 57, in _wrapfunc', '    return bound(*args, **kwds)', 'IndexError: index 9 is out of bounds for axis 0 with size 9']"
10,IndexError,index 9 is out of bounds for axis 0 with size 9,0,,2023-05-10 19:30:58.819134,"[('first_nine_waiting_times = faithful_with_eruption_nums.where(""eruption number"", are.between_or_equal_to(1, 9)).select(""waiting"").take(make_array(1, 2, 3, 4, 5, 6, 7, 8, 9))', 6), ('return self.__getitem__(all_args)', 5949)]","['Traceback (most recent call last):', '  File ""/opt/conda/lib/python3.10/site-packages/IPython/core/interactiveshell.py"", line 3508, in run_code', '    exec(code_obj, self.user_global_ns, self.user_ns)', '  File ""/tmp/ipykernel_129/2160343648.py"", line 6, in <module>', '    first_nine_waiting_times = faithful_with_eruption_nums.where(""eruption number"", are.between_or_equal_to(1, 9)).select(""waiting"").take(make_array(1, 2, 3, 4, 5, 6, 7, 8, 9))', '  File ""/opt/conda/lib/python3.10/site-packages/datascience/tables.py"", line 5949, in __call__', '    return self.__getitem__(all_args)', '  File ""/opt/conda/lib/python3.10/site-packages/datascience/tables.py"", line 6015, in __getitem__', '    columns = [np.take(column, row_indices_or_slice, axis=0)', '  File ""/opt/conda/lib/python3.10/site-packages/datascience/tables.py"", line 6015, in <listcomp>', '    columns = [np.take(column, row_indices_or_slice, axis=0)', '  File ""<__array_function__ internals>"", line 180, in take', '  File ""/opt/conda/lib/python3.10/site-packages/numpy/core/fromnumeric.py"", line 190, in take', ""    return _wrapfunc(a, 'take', indices, axis=axis, out=out, mode=mode)"", '  File ""/opt/conda/lib/python3.10/site-packages/numpy/core/fromnumeric.py"", line 57, in _wrapfunc', '    return bound(*args, **kwds)', 'IndexError: index 9 is out of bounds for axis 0 with size 9']"
11,IndentationError,"unexpected indent (3279711344.py, line 3)",0,,2023-05-10 19:44:05.162468,"[('return compile(source, filename, symbol, self.flags | PyCF_ONLY_AST, 1)', 86)]","['Traceback (most recent call last):', '  File ""/opt/conda/lib/python3.10/site-packages/IPython/core/interactiveshell.py"", line 3241, in run_cell_async', '    code_ast = compiler.ast_parse(cell, filename=cell_name)', '  File ""/opt/conda/lib/python3.10/site-packages/IPython/core/compilerop.py"", line 86, in ast_parse', '    return compile(source, filename, symbol, self.flags | PyCF_ONLY_AST, 1)', '  File ""/tmp/ipykernel_129/3279711344.py"", line 3', '    .with_columns(""fruit name"", make_array(""apples"", ""oranges"", ""pineapples""))', 'IndentationError: unexpected indent']"
12,SyntaxError,"'(' was never closed (3232346972.py, line 2)",0,,2023-05-10 19:44:27.778658,"[('return compile(source, filename, symbol, self.flags | PyCF_ONLY_AST, 1)', 86)]","['Traceback (most recent call last):', '  File ""/opt/conda/lib/python3.10/site-packages/IPython/core/interactiveshell.py"", line 3241, in run_cell_async', '    code_ast = compiler.ast_parse(cell, filename=cell_name)', '  File ""/opt/conda/lib/python3.10/site-packages/IPython/core/compilerop.py"", line 86, in ast_parse', '    return compile(source, filename, symbol, self.flags | PyCF_ONLY_AST, 1)', '  File ""/tmp/ipykernel_129/3232346972.py"", line 2', '    fruits = Table().with_columns(""fruit name"", make_array(""apples"", ""oranges"", ""pineapples"")).with_columns(""count"", make_array(4, 2, 3)', '                                                                                                           ^', ""SyntaxError: '(' was never closed""]"
13,IndentationError,"unexpected indent (3525786635.py, line 3)",0,,2023-05-10 19:44:55.450089,"[('return compile(source, filename, symbol, self.flags | PyCF_ONLY_AST, 1)', 86)]","['Traceback (most recent call last):', '  File ""/opt/conda/lib/python3.10/site-packages/IPython/core/interactiveshell.py"", line 3241, in run_cell_async', '    code_ast = compiler.ast_parse(cell, filename=cell_name)', '  File ""/opt/conda/lib/python3.10/site-packages/IPython/core/compilerop.py"", line 86, in ast_parse', '    return compile(source, filename, symbol, self.flags | PyCF_ONLY_AST, 1)', '  File ""/tmp/ipykernel_129/3525786635.py"", line 3', '    .with_columns(""count"", make_array(4, 2, 3))', 'IndentationError: unexpected indent']"
14,NameError,name 'arange' is not defined,0,,2023-05-10 20:34:08.851140,"[('first_nine_waiting_times = faithful_with_eruption_nums.take(arange(9)).column(""waiting"")', 6)]","['Traceback (most recent call last):', '  File ""/opt/conda/lib/python3.10/site-packages/IPython/core/interactiveshell.py"", line 3508, in run_code', '    exec(code_obj, self.user_global_ns, self.user_ns)', '  File ""/tmp/ipykernel_129/3941499216.py"", line 6, in <module>', '    first_nine_waiting_times = faithful_with_eruption_nums.take(arange(9)).column(""waiting"")', ""NameError: name 'arange' is not defined""]"
15,TypeError,'tuple' object is not callable,0,,2023-05-10 20:44:16.510638,"[('total_fruits_sold = sum(sales.columns(""count sold""))', 1)]","['Traceback (most recent call last):', '  File ""/opt/conda/lib/python3.10/site-packages/IPython/core/interactiveshell.py"", line 3508, in run_code', '    exec(code_obj, self.user_global_ns, self.user_ns)', '  File ""/tmp/ipykernel_129/56303049.py"", line 1, in <module>', '    total_fruits_sold = sum(sales.columns(""count sold""))', ""TypeError: 'tuple' object is not callable""]"
16,SyntaxError,"'(' was never closed (3422116587.py, line 1)",0,,2023-05-10 20:45:49.499446,"[('return compile(source, filename, symbol, self.flags | PyCF_ONLY_AST, 1)', 86)]","['Traceback (most recent call last):', '  File ""/opt/conda/lib/python3.10/site-packages/IPython/core/interactiveshell.py"", line 3241, in run_cell_async', '    code_ast = compiler.ast_parse(cell, filename=cell_name)', '  File ""/opt/conda/lib/python3.10/site-packages/IPython/core/compilerop.py"", line 86, in ast_parse', '    return compile(source, filename, symbol, self.flags | PyCF_ONLY_AST, 1)', '  File ""/tmp/ipykernel_129/3422116587.py"", line 1', '    total_revenue = sum(sales.column(""count sold"") * sales.column(""price per fruit ($)"")', '                       ^', ""SyntaxError: '(' was never closed""]"
